Workbook

Sheet README
A1: THE UNLOX ACADEMY - DA/DS TRACK
A2: Excel Minor Project - Sales Operations Analytics
A3: Interview-Grade Data Analytics Assessment · 100 Marks
A5: THE SCENARIO
A6: You have just joined the analytics team at a fast-growing multi-category retailer operating across 6 Indian cities.
A7: The head of sales has handed you 5 raw data files - Orders, Customers, Products, Sales Reps, and Targets - and asked
A8: you to answer a set of business questions before the leadership review tomorrow morning.
A10: The data is REAL-WORLD messy: duplicates, missing references, inconsistent case, invalid records, discontinued SKUs.
A11: Part of the assessment is spotting and handling these issues correctly. A wrong-looking answer isn't always wrong -
A12: sometimes the data itself is telling a story.
A14: RULES OF THE ASSESSMENT
A15: 1. Write your answer in the YELLOW cells on each question sheet. Empty answer cell = 0 marks.
... A22: MARKS DISTRIBUTION
A23: Section | B23: Topic | C23: Questions | D23: Marks
A24: Q1 | B24: Lookup Functions (VLOOKUP, INDEX-MATCH, chained lookups) | C24: 8 | D24: 25
A25: Q2 | B25: Data Cleaning & Quality Diagnostics | C25: 6 | D25: 20
A26: Q3 | B26: Conditional Aggregation (SUMIFS, COUNTIFS, IF logic) | C26: 6 | D26: 25
A27: Q4 | B27: Pivot Tables (2D pivots, % of total, calculated fields) | C27: 5 | D27: 20
A28: Q5 | B28: Advanced (Ranking, Running Totals, Multi-condition) | C28: 5 | D28: 10
B29: TOTAL | C29: 30 | D29: 100
A32: PERFORMANCE TIERS
A33: Marks | B33: Tier | C33: Interview Verdict
A34: 85 - 100 | B34: Excellent | C34: Round 1 clear - Excel not a concern
A35: 70 - 84 | B35: Good | C35: Round 1 clear with minor gaps
A36: 55 - 69 | B36: Borderline | C36: Round 1 uncertain - needs revision
A37: 40 - 54 | B37: Weak | C37: Round 1 likely reject - 2 weeks of practice needed
A38: < 40 | B38: Insufficient | C38: Round 1 reject - foundational gaps
A41: DATA SHEETS OVERVIEW
A42: Sheet | B42: Rows | C42: Key Columns | D42: Joins to
A43: Orders | B43: ~2000 | C43: order_id, order_date, customer_id, product_id, sales_rep_id, quantity, unit_price, discount_pct, final_amount, payment_status, ship_city | D43: All others
A44: Customers | B44: 300 | C44: customer_id (PK), customer_name, age, city, segment, signup_date | D44: Orders via customer_id
A45: Products | B45: 60 | C45: product_id (PK), product_name, category, unit_cost, unit_price, is_active | D45: Orders via product_id
A46: Sales_Reps | B46: 30 | C46: rep_id (PK), rep_name, region, hire_date, team_lead_id | D46: Orders via sales_rep_id, self-join via team_lead_id
A47: Targets | B47: 30 × 12 | C47: rep_id (PK), Jan-24 through Dec-24 monthly target values | D47: Sales_Reps via rep_id

Sheet Orders
A1: order_id | B1: order_date | C1: customer_id | D1: product_id | E1: sales_rep_id | F1: quantity | G1: unit_price | H1: discount_pct | I1: final_amount | J1: payment_status | K1: ship_city
A2: ORD-00001 | B2: 45549 | C2: CUST-0243 | D2: PROD-014 | E2: R007 | F2: 8 | G2: 3620 | H2: 15.4 | I2: 24500.16 | J2: Completed | K2: Pune
A3: ORD-00002 | B3: 45340 | C3: CUST-0202 | D3: PROD-020 | E3: R005 | F3: 2 | G3: 820 | H3: 10.8 | I3: 1462.88 | J3: Pending | K3: Chennai
A4: ORD-00003 | B4: 45371 | C4: CUST-0098 | D4: PROD-053 | E4: R014 | F4: 8 | G4: 470 | H4: 3.3 | I4: 3635.92 | J4: Pending | K4: Delhi
A5: ORD-00004 | B5: 45413 | C5: CUST-0071 | D5: PROD-028 | E5: R006 | F5: 1 | G5: 3660 | H5: 15.7 | I5: 3085.38 | J5: Completed | K5: Delhi
A6: ORD-00005 | B6: 45611 | C6: CUST-0180 | D6: PROD-012 | E6: R008 | F6: 1 | G6: 3160 | H6: 26 | I6: 2338.4 | J6: Completed | K6: Chennai
A7: ORD-00006 | B7: 45406 | C7: CUST-0275 | D7: PROD-032 | E7: R025 | F7: 4 | G7: 370 | H7: 29 | I7: 1050.8 | J7: Completed | K7: Mumbai
A8: ORD-00007 | B8: 45455 | C8: CUST-0293 | D8: PROD-057 | E8: R024 | F8: 3 | G8: 960 | H8: 5.8 | I8: 2712.96 | J8: Completed | K8: Bengaluru
A9: ORD-00008 | B9: 45617 | C9: CUST-0281 | D9: PROD-007 | E9: R019 | F9: 8 | G9: 1430 | H9: 2.4 | I9: 11165.44 | J9: Completed | K9: Bengaluru
A10: ORD-00009 | B10: 45549 | C10: CUST-0260 | D10: PROD-038 | E10: R008 | F10: 3 | G10: 5490 | H10: 14.2 | I10: 14131.26 | J10: Completed | K10: Bengaluru
A11: ORD-00010 | B11: 45396 | C11: CUST-0147 | D11: PROD-030 | E11: R028 | F11: 3 | G11: 970 | H11: 1.2 | I11: 2875.08 | J11: Completed | K11: Pune
A12: ORD-00011 | B12: 45560 | C12: CUST-0204 | D12: PROD-024 | E12: R010 | F12: 7 | G12: 2270 | H12: 7.1 | I12: 14761.81 | J12: Pending | K12: Hyderabad
A13: ORD-00012 | B13: 45332 | C13: CUST-0147 | D13: PROD-010 | E13: R024 | F13: 9 | G13: 2640 | H13: 21.7 | I13: 18604.08 | J13: Completed | K13: Pune
... A2001: ORD-02000 | B2001: 45325 | C2001: CUST-0238 | D2001: PROD-034 | E2001: R023 | F2001: 6 | G2001: 5080 | H2001: 28.1 | I2001: 21915.12 | J2001: Completed | K2001: Delhi

Sheet Customers
A1: customer_id | B1: customer_name | C1: age | D1: city | E1: segment | F1: signup_date
A2: CUST-0001 | B2: Amit Agarwal | C2: 36 | D2: Pune | E2: Retail | F2: 44819
A3: CUST-0002 | B3: Vihaan Malhotra | C3: 42 | D3: Pune | E3: Corporate | F3: 44984
A4: CUST-0003 | B4: Navya Malhotra | C4: 33 | D4: Mumbai | E4: Retail | F4: 44059
A5: CUST-0004 | B5: Aaradhya Mehta | C5: 53 | D5: delhi | E5: Retail | F5: 44054
A6: CUST-0005 | B6: Myra Malhotra | C6: 52 | D6: Chennai | E6: Corporate | F6: 45037
A7: CUST-0006 | B7: Shaurya Iyer | C7: 44 | D7: Pune | E7: SMB | F7: 44302
A8: CUST-0007 | B8: Dhruv Joshi | C8: 47 | D8: Bengaluru | E8: Retail | F8: 44498
A9: CUST-0008 | B9: Kavita Malhotra | C9: 39 | D9: Pune | E9: SMB | F9: 45162
A10: CUST-0009 | B10: Neha Malhotra | C10: 61 | D10: Mumbai | E10: Retail | F10: 44343
A11: CUST-0010 | B11: Aaradhya Gupta | C11: 61 | D11: Mumbai | E11: SMB | F11: 44975
A12: CUST-0011 | B12: Diya Menon | C12: 41 | D12: Chennai | E12: Corporate | F12: 44821
A13: CUST-0012 | B13: Prisha Desai | C13: 43 | D13: Pune | E13: Retail | F13: 44718
... A301: CUST-0300 | B301: Rohit Nair | C301: 38 | D301: Mumbai | E301: Retail | F301: 43932

Sheet Products
A1: product_id | B1: product_name | C1: category | D1: unit_cost | E1: unit_price | F1: is_active
A2: PROD-001 | B2: Smartphone Pro | C2: Electronics | D2: 2405 | E2: 5330 | F2: =TRUE() -> TRUE
A3: PROD-002 | B3: Wireless Earbuds | C3: Electronics | D3: 1052 | E3: 2600 | F3: =TRUE() -> TRUE
A4: PROD-003 | B4: Smart Watch | C4: Electronics | D4: 1665 | E4: 3570 | F4: =TRUE() -> TRUE
A5: PROD-004 | B5: Laptop Bag | C5: Electronics | D5: 1559 | E5: 3870 | F5: =TRUE() -> TRUE
A6: PROD-005 | B6: Power Bank | C6: Electronics | D6: 128 | E6: 300 | F6: =TRUE() -> TRUE
A7: PROD-006 | B7: Bluetooth Speaker | C7: Electronics | D7: 2865 | E7: 3970 | F7: =TRUE() -> TRUE
A8: PROD-007 | B8: USB-C Cable | C8: Electronics | D8: 861 | E8: 1430 | F8: =TRUE() -> TRUE
A9: PROD-008 | B9: Wireless Mouse | C9: Electronics | D9: 1259 | E9: 2660 | F9: =FALSE() -> FALSE
A10: PROD-009 | B10: Mechanical Keyboard | C10: Electronics | D10: 517 | E10: 1220 | F10: =TRUE() -> TRUE
A11: PROD-010 | B11: Tablet Stand | C11: Electronics | D11: 1149 | E11: 2640 | F11: =TRUE() -> TRUE
A12: PROD-011 | B12: Cotton T-Shirt | C12: Apparel | D12: 1748 | E12: 3450 | F12: =TRUE() -> TRUE
A13: PROD-012 | B13: Denim Jeans | C13: Apparel | D13: 1886 | E13: 3160 | F13: =TRUE() -> TRUE
A14: PROD-013 | B14: Formal Shirt | C14: Apparel | D14: 2611 | E14: 3640 | F14: =TRUE() -> TRUE
A15: PROD-014 | B15: Winter Jacket | C15: Apparel | D15: 2509 | E15: 3620 | F15: =TRUE() -> TRUE
A16: PROD-015 | B16: Sports Shoes | C16: Apparel | D16: 1962 | E16: 2720 | F16: =TRUE() -> TRUE
A17: PROD-016 | B17: Casual Sneakers | C17: Apparel | D17: 396 | E17: 620 | F17: =TRUE() -> TRUE
A18: PROD-017 | B18: Silk Saree | C18: Apparel | D18: 1075 | E18: 2510 | F18: =FALSE() -> FALSE
A19: PROD-018 | B19: Kurta Set | C19: Apparel | D19: 2629 | E19: 3560 | F19: =TRUE() -> TRUE
A20: PROD-019 | B20: Track Pants | C20: Apparel | D20: 1173 | E20: 2480 | F20: =TRUE() -> TRUE
A21: PROD-020 | B21: Woolen Sweater | C21: Apparel | D21: 391 | E21: 820 | F21: =TRUE() -> TRUE
A22: PROD-021 | B22: Basmati Rice 5kg | C22: Grocery | D22: 1435 | E22: 2760 | F22: =TRUE() -> TRUE
A23: PROD-022 | B23: Wheat Flour 10kg | C23: Grocery | D23: 1412 | E23: 2270 | F23: =TRUE() -> TRUE
A24: PROD-023 | B24: Cooking Oil 5L | C24: Grocery | D24: 1182 | E24: 2380 | F24: =TRUE() -> TRUE
A25: PROD-024 | B25: Turmeric Powder 500g | C25: Grocery | D25: 1203 | E25: 2270 | F25: =TRUE() -> TRUE
A26: PROD-025 | B26: Chili Powder 500g | C26: Grocery | D26: 2911 | E26: 4060 | F26: =TRUE() -> TRUE
A27: PROD-026 | B27: Sugar 5kg | C27: Grocery | D27: 2027 | E27: 4070 | F27: =TRUE() -> TRUE
A28: PROD-027 | B28: Tea Leaves 1kg | C28: Grocery | D28: 2436 | E28: 3780 | F28: =TRUE() -> TRUE
A29: PROD-028 | B29: Coffee Beans 500g | C29: Grocery | D29: 2214 | E29: 3660 | F29: =FALSE() -> FALSE
A30: PROD-029 | B30: Ghee 1L | C30: Grocery | D30: 1010 | E30: 2210 | F30: =TRUE() -> TRUE
A31: PROD-030 | B31: Salt 1kg | C31: Grocery | D31: 434 | E31: 970 | F31: =TRUE() -> TRUE
A32: PROD-031 | B32: Bed Sheet Set | C32: Home | D32: 2135 | E32: 3730 | F32: =TRUE() -> TRUE
A33: PROD-032 | B33: Pillow Cover Pair | C33: Home | D33: 288 | E33: 370 | F33: =TRUE() -> TRUE
A34: PROD-033 | B34: Curtain Set | C34: Home | D34: 1143 | E34: 2030 | F34: =TRUE() -> TRUE
A35: PROD-034 | B35: Kitchen Towel Set | C35: Home | D35: 2459 | E35: 5080 | F35: =TRUE() -> TRUE
A36: PROD-035 | B36: Doormat | C36: Home | D36: 464 | E36: 1090 | F36: =TRUE() -> TRUE
A37: PROD-036 | B37: Wall Clock | C37: Home | D37: 1556 | E37: 3250 | F37: =TRUE() -> TRUE
A38: PROD-037 | B38: Table Lamp | C38: Home | D38: 329 | E38: 660 | F38: =TRUE() -> TRUE
A39: PROD-038 | B39: Storage Box | C39: Home | D39: 2549 | E39: 5490 | F39: =TRUE() -> TRUE
A40: PROD-039 | B40: Photo Frame | C40: Home | D40: 1850 | E40: 4610 | F40: =TRUE() -> TRUE
...

Sheet Sales_Reps
A1: rep_id | B1: rep_name | C1: region | D1: hire_date | E1: team_lead_id
A2: R001 | B2: Rajesh Malhotra | C2: North | D2: 44207
A3: R002 | B3: Sunita Malhotra | C3: North | D3: 44028
A4: R003 | B4: Amit Singh | C4: North | D4: 43651
A5: R004 | B5: Priya Singh | C5: North | D5: 44907
A6: R005 | B6: Vikram Patel | C6: North | D6: 43588 | E6: R001
A7: R006 | B7: Neha Desai | C7: North | D7: 44131 | E7: R001
A8: R007 | B8: Suresh Menon | C8: North | D8: 43493 | E8: R001
A9: R008 | B9: Kavita Patel | C9: North | D9: 44693 | E9: R001
A10: R009 | B10: Manoj Patel | C10: South | D10: 44804 | E10: R002
A11: R010 | B11: Divya Rao | C11: South | D11: 43904 | E11: R002
A12: R011 | B12: Anil Verma | C12: South | D12: 44622 | E12: R002
A13: R012 | B13: Pooja Nair | C13: South | D13: 44890 | E13: R002
A14: R013 | B14: Sanjay Kapoor | C14: South | D14: 45215 | E14: R002
A15: R014 | B15: Ritu Menon | C15: South | D15: 44469 | E15: R002
A16: R015 | B16: Deepak Shah | C16: South | D16: 45231 | E16: R002
A17: R016 | B17: Anjali Chopra | C17: South | D17: 43614 | E17: R002
... A31: R030 | B31: Kiran Bhatt | C31: West | D31: 44506 | E31: R004

Sheet Targets
A1: rep_id | B1: Jan-24 | C1: Feb-24 | D1: Mar-24 | E1: Apr-24 | F1: May-24 | G1: Jun-24 | H1: Jul-24 | I1: Aug-24 | J1: Sep-24 | K1: Oct-24 | L1: Nov-24 | M1: Dec-24
A2: R001 | B2: 231324 | C2: 171682 | D2: 234376 | E2: 326967 | F2: 350588 | G2: 385324 | H2: 307980 | I2: 327947 | J2: 181016 | K2: 374039 | L2: 212805 | M2: 405999
A3: R002 | B3: 438126 | C3: 346266 | D3: 329993 | E3: 370744 | F3: 294660 | G3: 341556 | H3: 151934 | I3: 223794 | J3: 438641 | K3: 344308 | L3: 296172 | M3: 304288
A4: R003 | B4: 358703 | C4: 320519 | D4: 327321 | E4: 298753 | F4: 254636 | G4: 351929 | H4: 264723 | I4: 216459 | J4: 391945 | K4: 362426 | L4: 289199 | M4: 301863
A5: R004 | B5: 389594 | C5: 376422 | D5: 324156 | E5: 420255 | F5: 409107 | G5: 269954 | H5: 179097 | I5: 370568 | J5: 387395 | K5: 243454 | L5: 232530 | M5: 201999
A6: R005 | B6: 436862 | C6: 391158 | D6: 340224 | E6: 170548 | F6: 229390 | G6: 349525 | H6: 154683 | I6: 320848 | J6: 354452 | K6: 377180 | L6: 342347 | M6: 183362
A7: R006 | B7: 348734 | C7: 358191 | D7: 250385 | E7: 219657 | F7: 249365 | G7: 435704 | H7: 260892 | I7: 250741 | J7: 358402 | K7: 379858 | L7: 213280 | M7: 224634
A8: R007 | B8: 280057 | C8: 330342 | D8: 336856 | E8: 227425 | F8: 233647 | G8: 307088 | H8: 370724 | I8: 440008 | J8: 406347 | K8: 217357 | L8: 299289 | M8: 214568
A9: R008 | B9: 252886 | C9: 206057 | D9: 318209 | E9: 411230 | F9: 448660 | G9: 171135 | H9: 305339 | I9: 432264 | J9: 294273 | K9: 371409 | L9: 284207 | M9: 437068
A10: R009 | B10: 268752 | C10: 393256 | D10: 310649 | E10: 246237 | F10: 271287 | G10: 314545 | H10: 406506 | I10: 334930 | J10: 348625 | K10: 408928 | L10: 243749 | M10: 418409
A11: R010 | B11: 384734 | C11: 156698 | D11: 283679 | E11: 276085 | F11: 409270 | G11: 285230 | H11: 304233 | I11: 178221 | J11: 284216 | K11: 287373 | L11: 229082 | M11: 298969
A12: R011 | B12: 186029 | C12: 151419 | D12: 253251 | E12: 379757 | F12: 204209 | G12: 179396 | H12: 378008 | I12: 182649 | J12: 267772 | K12: 350352 | L12: 358042 | M12: 359960
A13: R012 | B13: 352158 | C13: 251181 | D13: 321255 | E13: 300863 | F13: 241731 | G13: 393275 | H13: 313561 | I13: 283604 | J13: 429065 | K13: 194420 | L13: 254168 | M13: 389283
... A31: R030 | B31: 151584 | C31: 221679 | D31: 385157 | E31: 290386 | F31: 236041 | G31: 407985 | H31: 184446 | I31: 342894 | J31: 180344 | K31: 292917 | L31: 314858 | M31: 364057

Sheet Q1_Lookups
A1: Q1 - LOOKUP FUNCTIONS (25 marks total)
A2: VLOOKUP · INDEX-MATCH · Two-way lookup · Chain lookup · Approximate lookup · Self-join
A4: Q# | B4: Question | C4: Marks | D4: Hint | E4: Your Answer | F4: Format
A5: Q1.1 | B5: For order ORD-00234, what is the customer_id? | C5: 3 | D5: Simple VLOOKUP on Orders sheet. | E5: =VLOOKUP("ORD-00234",Orders!$A:$K,3,FALSE()) -> CUST-0173 | F5: CUST-####
A6: Q1.2 | B6: For order ORD-00456, what is the product_name? (You will need to look up the product_id first, then find its name in Products.) | C6: 3 | D6: Two-step lookup, or nested VLOOKUP. | E6: =VLOOKUP(VLOOKUP("ORD-00456",Orders!$A:$K,4,FALSE()),Products!$A:$F,2,FALSE()) -> Dumbbells 5kg | F6: Text
A7: Q1.3 | B7: For order ORD-00987, what is the rep_name of the sales rep? Note: the rep_name is in a column that appears to the LEFT of what you might look up first. | C7: 3 | D7: VLOOKUP has directional limits - INDEX/MATCH does not. | E7: =INDEX(Sales_Reps!$B:$B,MATCH(INDEX(Orders!$E:$E,MATCH("ORD-00987",Orders!$A:$A,0)),Sales_Reps!$A:$A,0)) -> Nisha Menon | F7: Text
A8: Q1.4 | B8: From the Targets sheet, what is the target value for rep R012 in the month Mar-24? | C8: 4 | D8: Two-way lookup: row = rep_id, column = month. | E8: =INDEX(Targets!$B$2:$M$31,MATCH("R012",Targets!$A$2:$A$31,0),MATCH("Mar-24",Targets!$B$1:$M$1,0)) -> 321255 | F8: Whole number
A9: Q1.5 | B9: For order ORD-01500, what is the CATEGORY of the product ordered? (Chain: order → product_id → category) | C9: 4 | D9: Multi-hop lookup across sheets. | E9: =VLOOKUP(VLOOKUP("ORD-01500",Orders!$A:$K,4,FALSE()),Products!$A:$F,3,FALSE()) -> Electronics | F9: Text
A10: Q1.6 | B10: For order ORD-00789, which DISCOUNT SLAB does it fall in? Use the slab table below (rows 20-24). Slab breakpoints are the LOWER bound of each range. | C10: 3 | D10: Approximate-match VLOOKUP (sort ascending, TRUE / omit last arg). | E10: =VLOOKUP(VLOOKUP("ORD-00789",Orders!$A:$K,8,FALSE()),$B$18:$C$21,2,TRUE()) -> Bronze | F10: Text
A11: Q1.7 | B11: For order ORD-01234, in one cell produce the string: "<rep_name> (<sales_region>)" - e.g. "Amit Singh (South)". | C11: 3 | D11: Two lookups joined with & or CONCATENATE. | E11: =INDEX(Sales_Reps!$B:$B,MATCH(INDEX(Orders!$E:$E,MATCH("ORD-01234",Orders!$A:$A,0)),Sales_Reps!$A:$A,0))&" ("&INDEX(Sales_Reps!$C:$C,MATCH(INDEX(Orders!$E:$E,MATCH("ORD-01234",Orders!$A:$A,0)),Sales_Reps!$A:$A,0))&")" -> Sanjay Kapoor (South) | F11: Text
A12: Q1.8 | B12: What is the rep_name of the TEAM LEAD for rep R017? (The Sales_Reps sheet has team_lead_id - you need to self-join to find that person's name.) | C12: 2 | D12: Look up the team_lead_id, then look up THAT id's rep_name. | E12: =INDEX(Sales_Reps!$B:$B,MATCH(INDEX(Sales_Reps!$E:$E,MATCH("R017",Sales_Reps!$A:$A,0)),Sales_Reps!$A:$A,0)) -> Amit Singh | F12: Text
B15: DISCOUNT SLAB REFERENCE TABLE (use for Q1.6)
B17: Discount % (Lower) | C17: Slab
B18: 0 | C18: Bronze
B19: 5 | C19: Silver
B20: 15 | C20: Gold
B21: 25 | C21: Platinum

Sheet Q2_Cleaning
A1: Q2 - DATA CLEANING & QUALITY DIAGNOSTICS (20 marks total)
A2: Duplicates · Whitespace · Case Inconsistency · Referential Integrity · Discontinued SKUs · Anomaly Patterns
A4: Q# | B4: Question | C4: Marks | D4: Hint | E4: Your Answer | F4: Format
A5: Q2.1 | B5: How many DUPLICATE rows exist in the Orders sheet (i.e., how many order_id values appear more than once)? Count each duplicate as ONE (not the extras). | C5: 3 | D5: COUNTIF > 1, then count. Watch what you're counting - rows or IDs. | E5: =SUMPRODUCT((COUNTIF(Orders!$A$2:$A$2001,Orders!$A$2:$A$2001)>1)/COUNTIF(Orders!$A$2:$A$2001,Orders!$A$2:$A$2001)) -> 20 | F5: Whole number
A6: Q2.2 | B6: How many customers in the Customers sheet have LEADING or TRAILING whitespace in their customer_name? | C6: 3 | D6: Compare LEN vs LEN(TRIM). Or use SUMPRODUCT with a boolean. | E6: =SUMPRODUCT(--(LEN(Customers!$B$2:$B$301)<>LEN(TRIM(Customers!$B$2:$B$301)))) -> 15 | F6: Whole number
A7: Q2.3 | B7: The Customers sheet has some cities in inconsistent case (e.g., "mumbai", "MUMBAI", "Mumbai"). How many DISTINCT cities exist AFTER standardizing case? | C7: 3 | D7: Combine PROPER/UPPER with a de-dup count. SUMPRODUCT + 1/COUNTIF trick works. | E7: =SUMPRODUCT(1/COUNTIF(Customers!$D$2:$D$301,TRIM(Customers!$D$2:$D$301))) -> 6 | F7: Whole number
A8: Q2.4 | B8: How many orders reference a customer_id that DOES NOT EXIST in the Customers sheet? (Broken foreign key) | C8: 4 | D8: Use MATCH with ISNA/ISERROR, then count. | E8: =SUMPRODUCT(--ISNA(MATCH(Orders!$C$2:$C$2001,Customers!$A$2:$A$301,0))) -> 30 | F8: Whole number
A9: Q2.5 | B9: How many orders reference a product that is currently DISCONTINUED (is_active = FALSE in the Products sheet)? | C9: 3 | D9: VLOOKUP the is_active flag, then count where FALSE. | E9: =SUMPRODUCT(COUNTIF(Orders!$D$2:$D$2001,Products!$A$2:$A$61)*(Products!$F$2:$F$61=FALSE())) -> 174 | F9: Whole number
A10: Q2.6 | B10: Find the "suspicious pattern": how many orders have payment_status = "Cancelled" AND a discount_pct > 20%? (This pattern often indicates promo abuse - a real-world diagnostic query.) | C10: 4 | D10: COUNTIFS with two criteria. | E10: =COUNTIFS(Orders!$J$2:$J$2001,"Cancelled",Orders!$H$2:$H$2001,">20") -> 58 | F10: Whole number

Sheet Q3_Aggregation
A1: Q3 - CONDITIONAL AGGREGATION (25 marks total)
A2: SUMIFS · COUNTIFS · AVERAGEIFS · Nested IF logic · Multi-sheet aggregation · Top-N logic
A4: Q# | B4: Question | C4: Marks | D4: Hint | E4: Your Answer | F4: Format
A5: Q3.1 | B5: What is the TOTAL REVENUE (sum of final_amount) for orders in Q3 2024 (Jul-Sep) where ship_city is Mumbai? | C5: 4 | D5: SUMIFS with 3 conditions: date >= start, date <= end, city = Mumbai. Beware case issues. | E5: =SUMIFS(Orders!$I$2:$I$2001,Orders!$B$2:$B$2001,">="&DATE(2024,7,1),Orders!$B$2:$B$2001,"<"&DATE(2024,10,1),Helper!$B$2:$B$2001,"Mumbai") -> 1217239 | F5: Currency
A6: Q3.2 | B6: How many orders have discount_pct > 15% AND payment_status = "Completed"? | C6: 3 | D6: COUNTIFS with two conditions. | E6: =COUNTIFS(Orders!$H$2:$H$2001,">15",Orders!$J$2:$J$2001,"Completed") -> 723 | F6: Whole number
A7: Q3.3 | B7: What is the AVERAGE final_amount for orders where the product CATEGORY is "Electronics" AND the customer SEGMENT is "Corporate"? Note: Both fields come from OTHER sheets - you'll need helper columns. | C7: 5 | D7: Helper columns in Orders: VLOOKUP category from Products, VLOOKUP segment from Customers. Then AVERAGEIFS. | E7: =AVERAGEIFS(Orders!$I$2:$I$2001,Helper!$C$2:$C$2001,"Electronics",Helper!$D$2:$D$2001,"Corporate") -> 13981.402 | F7: Currency
A8: Q3.4 | B8: What is the COMBINED REVENUE of the TOP 3 reps by total revenue? (Sum of the 3 highest rep totals.) | C8: 4 | D8: Compute per-rep totals, then use SUMPRODUCT with LARGE, or sort and sum top 3. | E8: =SUMPRODUCT(LARGE(Helper!$L$2:$L$31,{1,2,3})) -> 3342678.5 | F8: Currency
A9: Q3.5 | B9: For rep R015 in Nov-24: compute the actual revenue and compare to the target (from Targets sheet). Report the PERFORMANCE TIER using: <80% → "Below", 80-120% → "On Track", >120% → "Exceeds". Return only the tier text. | C9: 5 | D9: Nested IF (or IFS): compute actual/target ratio, then classify. | E9: =IF(SUMIFS(Orders!$I$2:$I$2001,Orders!$E$2:$E$2001,"R015",Orders!$B$2:$B$2001,">="&DATE(2024,11,1),Orders!$B$2:$B$2001,"<"&DATE(2024,12,1))/INDEX(Targets!$B$2:$M$31,MATCH("R015",Targets!$A$2:$A$31,0),MATCH("Nov-24",Targets!$B$1:$M$1,0))<0.8,"Below",IF(SUMIFS(Orders!$I$2:$I$2001,Orders!$E$2:$E$2001,"R015",Orders!$B$2:$B$2001,">="&DATE(2024,11,1),Orders!$B$2:$B$2001,"<"&DATE(2024,12,1))/INDEX(Targets!$B$2:$M$31,MATCH("R015",Targets!$A$2:$A$31,0),MATCH("Nov-24",Targets!$B$1:$M$1,0))<=1.2,"On Track","Exceeds")) -> Below | F9: Text
A10: Q3.6 | B10: What is the TOTAL revenue from Corporate segment customers aged between 30 and 40 (both inclusive)? | C10: 4 | D10: Helper columns for age and segment. Then SUMIFS with numeric range. | E10: =SUMIFS(Orders!$I$2:$I$2001,Helper!$D$2:$D$2001,"Corporate",Helper!$E$2:$E$2001,">=30",Helper!$E$2:$E$2001,"<=40") -> 982568.4 | F10: Currency

Sheet Q4_Pivot
A1: Q4 - PIVOT TABLES (20 marks total)
A2: 2D Pivots · Filters · % of Row Total · Date Grouping · Calculated Fields · Cross-Sheet Data
A4: Q# | B4: Question | C4: Marks | D4: Hint | E4: Your Answer | F4: Format
A5: Q4.1 | B5: Build a pivot with sales_region as rows and product category as columns, values = SUM of final_amount. What value appears at the intersection of "South" and "Electronics"? | C5: 4 | D5: You need to add category (from Products) and region (from Sales_Reps) as columns to Orders first. Insert PivotTable from combined data. | E5: =SUMIFS(Orders!$I$2:$I$2001,Helper!$F$2:$F$2001,"South",Helper!$C$2:$C$2001,"Electronics") -> 1314107.4 | F5: Currency
A6: Q4.2 | B6: Build a pivot: rows = order month (Jan-24 through Dec-24), columns = sales_rep_id, values = SUM of final_amount. What is the HIGHEST single value in the entire pivot? (One number.) | C6: 4 | D6: After building, use MAX() over the pivot data range, or scan visually. | E6: =MAX(Helper!$W$2:$AZ$13) -> 216421.52 | F6: Currency
A7: Q4.3 | B7: For the North sales_region only: what PERCENTAGE of total revenue comes from the Apparel category? Configure the pivot with Show Values As → % of Row Total. | C7: 4 | D7: Pivot: rows=region, cols=category, values=sum(final_amount), Show Values As = % of Row Total. | E7: =SUMIFS(Orders!$I$2:$I$2001,Helper!$F$2:$F$2001,"North",Helper!$C$2:$C$2001,"Apparel")/SUMIFS(Orders!$I$2:$I$2001,Helper!$F$2:$F$2001,"North") -> 0.1402315 | F7: Percentage
A8: Q4.4 | B8: Group order dates by QUARTER in a pivot. What is the total revenue for Q4 2024 (Oct-Dec)? | C8: 4 | D8: PivotTable → Group By → Quarter. Or SUMIFS with date range. | E8: =SUMIFS(Orders!$I$2:$I$2001,Orders!$B$2:$B$2001,">="&DATE(2024,10,1),Orders!$B$2:$B$2001,"<"&DATE(2025,1,1)) -> 6459443 | F8: Currency
A9: Q4.5 | B9: Create a CALCULATED FIELD in the pivot: profit_margin = (unit_price - unit_cost) / unit_price. What is the AVERAGE profit_margin for orders shipped to Delhi? Give as a percentage. | C9: 4 | D9: Add unit_cost via VLOOKUP as helper column. Create pivot calculated field, filter to Delhi. | E9: =AVERAGEIFS(Helper!$H$2:$H$2001,Helper!$B$2:$B$2001,"Delhi") -> 0.44903865 | F9: Percentage

Sheet Q5_Advanced
A1: Q5 - ADVANCED (10 marks total)
A2: RANK · Running Totals · TEXTJOIN · LARGE + INDEX/MATCH · Multi-condition top-N
A4: Q# | B4: Question | C4: Marks | D4: Hint | E4: Your Answer | F4: Format
A5: Q5.1 | B5: Rank all sales reps by total revenue (highest = rank 1). Who (name) is at RANK #7? | C5: 2 | D5: Per-rep totals, then use RANK.EQ, or sort. Return the rep_name at position 7. | E5: =INDEX(Helper!$K$2:$K$31,MATCH(7,Helper!$M$2:$M$31,0)) -> Amit Singh | F5: Text
A6: Q5.2 | B6: What is the CUMULATIVE revenue from Jan 2024 through the end of Aug 2024? (Sum of final_amount where order_date <= 31-Aug-2024.) | C6: 2 | D6: SUMIFS with date <=. | E6: =SUMIFS(Orders!$I$2:$I$2001,Orders!$B$2:$B$2001,"<"&DATE(2024,9,1)) -> 18050690 | F6: Currency
A7: Q5.3 | B7: Among orders where the sales rep is in the WEST region: which product (by name) has the 2nd highest total revenue? | C7: 3 | D7: Helper: sales_region on orders. Filter/pivot to West, sum by product, rank, get #2, VLOOKUP product name. | E7: =INDEX(Helper!$S$2:$S$61,MATCH(LARGE(Helper!$T$2:$T$61,2),Helper!$T$2:$T$61,0)) -> Smart Watch | F7: Text
A8: Q5.4 | B8: Concatenate the names of the top 5 reps by revenue into a single cell, separated by " | " (space-pipe-space). | C8: 2 | D8: TEXTJOIN with delimiter " | ". Combine with LARGE to pull top 5. | E8: =_xlfn.TEXTJOIN(" | ",TRUE(),Helper!$P$2:$P$6) -> Neha Desai | Shalini Patel | Deepak Shah | Nisha Menon | Arun Iyer | F8: Text
A9: Q5.5 | B9: What is the HIGHEST single order value (final_amount) where ship_city = "Bengaluru" AND the product's category = "Grocery"? | C9: 1 | D9: MAXIFS with a category helper column, or nested MAX(IF()). | E9: =_xlfn.MAXIFS(Orders!$I$2:$I$2001,Helper!$B$2:$B$2001,"Bengaluru",Helper!$C$2:$C$2001,"Grocery") -> 22134 | F9: Currency

Sheet Helper
A1: order_id | B1: ship_city_clean | C1: category | D1: segment | E1: age | F1: sales_region | G1: unit_cost | H1: profit_margin | J1: rep_id | K1: rep_name | L1: total_revenue | M1: rank | O1: top_n | P1: rep_name (top 5) | R1: product_id | S1: product_name | T1: west_revenue | V1: month \ rep_id | W1: =INDEX(Sales_Reps!$A$2:$A$31,1) -> R001 | X1: =INDEX(Sales_Reps!$A$2:$A$31,2) -> R002 | Y1: =INDEX(Sales_Reps!$A$2:$A$31,3) -> R003 | Z1: =INDEX(Sales_Reps!$A$2:$A$31,4) -> R004 | AA1: =INDEX(Sales_Reps!$A$2:$A$31,5) -> R005 | AB1: =INDEX(Sales_Reps!$A$2:$A$31,6) -> R006 | AC1: =INDEX(Sales_Reps!$A$2:$A$31,7) -> R007 | AD1: =INDEX(Sales_Reps!$A$2:$A$31,8) -> R008 | AE1: =INDEX(Sales_Reps!$A$2:$A$31,9) -> R009 | AF1: =INDEX(Sales_Reps!$A$2:$A$31,10) -> R010 | AG1: =INDEX(Sales_Reps!$A$2:$A$31,11) -> R011 | AH1: =INDEX(Sales_Reps!$A$2:$A$31,12) -> R012 | AI1: =INDEX(Sales_Reps!$A$2:$A$31,13) -> R013 | AJ1: =INDEX(Sales_Reps!$A$2:$A$31,14) -> R014 | AK1: =INDEX(Sales_Reps!$A$2:$A$31,15) -> R015 | AL1: =INDEX(Sales_Reps!$A$2:$A$31,16) -> R016 | AM1: =INDEX(Sales_Reps!$A$2:$A$31,17) -> R017 | AN1: =INDEX(Sales_Reps!$A$2:$A$31,18) -> R018 | AO1: =INDEX(Sales_Reps!$A$2:$A$31,19) -> R019 | AP1: =INDEX(Sales_Reps!$A$2:$A$31,20) -> R020 | AQ1: =INDEX(Sales_Reps!$A$2:$A$31,21) -> R021 | AR1: =INDEX(Sales_Reps!$A$2:$A$31,22) -> R022 | AS1: =INDEX(Sales_Reps!$A$2:$A$31,23) -> R023 | AT1: =INDEX(Sales_Reps!$A$2:$A$31,24) -> R024 | AU1: =INDEX(Sales_Reps!$A$2:$A$31,25) -> R025 | AV1: =INDEX(Sales_Reps!$A$2:$A$31,26) -> R026 | AW1: =INDEX(Sales_Reps!$A$2:$A$31,27) -> R027 | AX1: =INDEX(Sales_Reps!$A$2:$A$31,28) -> R028 | AY1: =INDEX(Sales_Reps!$A$2:$A$31,29) -> R029 | AZ1: =INDEX(Sales_Reps!$A$2:$A$31,30) -> R030
A2: =Orders!A2 -> ORD-00001 | B2: =PROPER(TRIM(Orders!K2)) -> Pune | C2: =IFERROR(VLOOKUP(Orders!D2,Products!$A$2:$F$61,3,FALSE()),"Not Found") -> Apparel | D2: =IFERROR(VLOOKUP(Orders!C2,Customers!$A$2:$F$301,5,FALSE()),"Not Found") -> SMB | E2: =IFERROR(VLOOKUP(Orders!C2,Customers!$A$2:$F$301,3,FALSE()),"Not Found") -> 44 | F2: =IFERROR(VLOOKUP(Orders!E2,Sales_Reps!$A$2:$E$31,3,FALSE()),"Not Found") -> North | G2: =IFERROR(VLOOKUP(Orders!D2,Products!$A$2:$F$61,4,FALSE()),"") -> 2509 | H2: =IF(G2="","",(Orders!G2-G2)/Orders!G2) -> 0.30690608 | J2: =Sales_Reps!A2 -> R001 | K2: =Sales_Reps!B2 -> Rajesh Malhotra | L2: =SUMIFS(Orders!$I$2:$I$2001,Orders!$E$2:$E$2001,J2) -> 789849.6 | M2: =RANK(L2,$L$2:$L$31,0) -> 23 | O2: 1 | P2: =INDEX($K$2:$K$31,MATCH(LARGE($L$2:$L$31,O2),$L$2:$L$31,0)) -> Neha Desai | R2: =Products!A2 -> PROD-001 | S2: =Products!B2 -> Smartphone Pro | T2: =SUMIFS(Orders!$I$2:$I$2001,Orders!$D$2:$D$2001,R2,$F$2:$F$2001,"West") -> 155358.84 | V2: =DATE(2024,1,1) -> 45292 | W2: =SUMIFS(Orders!$I$2:$I$2001,Orders!$B$2:$B$2001,">="&$V2,Orders!$B$2:$B$2001,"<"&EDATE($V2,1),Orders!$E$2:$E$2001,W$1) -> 43650.56 | X2: =SUMIFS(Orders!$I$2:$I$2001,Orders!$B$2:$B$2001,">="&$V2,Orders!$B$2:$B$2001,"<"&EDATE($V2,1),Orders!$E$2:$E$2001,X$1) -> 51707.32 | Y2: =SUMIFS(Orders!$I$2:$I$2001,Orders!$B$2:$B$2001,">="&$V2,Orders!$B$2:$B$2001,"<"&EDATE($V2,1),Orders!$E$2:$E$2001,Y$1) -> 54307 | Z2: =SUMIFS(Orders!$I$2:$I$2001,Orders!$B$2:$B$2001,">="&$V2,Orders!$B$2:$B$2001,"<"&EDATE($V2,1),Orders!$E$2:$E$2001,Z$1) -> 57892.11 | AA2: =SUMIFS(Orders!$I$2:$I$2001,Orders!$B$2:$B$2001,">="&$V2,Orders!$B$2:$B$2001,"<"&EDATE($V2,1),Orders!$E$2:$E$2001,AA$1) -> 70665.51 | AB2: =SUMIFS(Orders!$I$2:$I$2001,Orders!$B$2:$B$2001,">="&$V2,Orders!$B$2:$B$2001,"<"&EDATE($V2,1),Orders!$E$2:$E$2001,AB$1) -> 84968.56 | AC2: =SUMIFS(Orders!$I$2:$I$2001,Orders!$B$2:$B$2001,">="&$V2,Orders!$B$2:$B$2001,"<"&EDATE($V2,1),Orders!$E$2:$E$2001,AC$1) -> 92029.91 | AD2: =SUMIFS(Orders!$I$2:$I$2001,Orders!$B$2:$B$2001,">="&$V2,Orders!$B$2:$B$2001,"<"&EDATE($V2,1),Orders!$E$2:$E$2001,AD$1) -> 61557.02 | ... AZ2: =SUMIFS(Orders!$I$2:$I$2001,Orders!$B$2:$B$2001,">="&$V2,Orders!$B$2:$B$2001,"<"&EDATE($V2,1),Orders!$E$2:$E$2001,AZ$1) -> 59170.81
A3: =Orders!A3 -> ORD-00002 | B3: =PROPER(TRIM(Orders!K3)) -> Chennai | C3: =IFERROR(VLOOKUP(Orders!D3,Products!$A$2:$F$61,3,FALSE()),"Not Found") -> Apparel | D3: =IFERROR(VLOOKUP(Orders!C3,Customers!$A$2:$F$301,5,FALSE()),"Not Found") -> Retail | E3: =IFERROR(VLOOKUP(Orders!C3,Customers!$A$2:$F$301,3,FALSE()),"Not Found") -> 39 | F3: =IFERROR(VLOOKUP(Orders!E3,Sales_Reps!$A$2:$E$31,3,FALSE()),"Not Found") -> North | G3: =IFERROR(VLOOKUP(Orders!D3,Products!$A$2:$F$61,4,FALSE()),"") -> 391 | H3: =IF(G3="","",(Orders!G3-G3)/Orders!G3) -> 0.52317073 | J3: =Sales_Reps!A3 -> R002 | K3: =Sales_Reps!B3 -> Sunita Malhotra | L3: =SUMIFS(Orders!$I$2:$I$2001,Orders!$E$2:$E$2001,J3) -> 980063.66 | M3: =RANK(L3,$L$2:$L$31,0) -> 9 | O3: 2 | P3: =INDEX($K$2:$K$31,MATCH(LARGE($L$2:$L$31,O3),$L$2:$L$31,0)) -> Shalini Patel | R3: =Products!A3 -> PROD-002 | S3: =Products!B3 -> Wireless Earbuds | T3: =SUMIFS(Orders!$I$2:$I$2001,Orders!$D$2:$D$2001,R3,$F$2:$F$2001,"West") -> 105284.4 | V3: =EDATE(V2,1) -> 45323 | W3: =SUMIFS(Orders!$I$2:$I$2001,Orders!$B$2:$B$2001,">="&$V3,Orders!$B$2:$B$2001,"<"&EDATE($V3,1),Orders!$E$2:$E$2001,W$1) -> 127005.17 | X3: =SUMIFS(Orders!$I$2:$I$2001,Orders!$B$2:$B$2001,">="&$V3,Orders!$B$2:$B$2001,"<"&EDATE($V3,1),Orders!$E$2:$E$2001,X$1) -> 125187.78 | Y3: =SUMIFS(Orders!$I$2:$I$2001,Orders!$B$2:$B$2001,">="&$V3,Orders!$B$2:$B$2001,"<"&EDATE($V3,1),Orders!$E$2:$E$2001,Y$1) -> 32452 | Z3: =SUMIFS(Orders!$I$2:$I$2001,Orders!$B$2:$B$2001,">="&$V3,Orders!$B$2:$B$2001,"<"&EDATE($V3,1),Orders!$E$2:$E$2001,Z$1) -> 58818.56 | AA3: =SUMIFS(Orders!$I$2:$I$2001,Orders!$B$2:$B$2001,">="&$V3,Orders!$B$2:$B$2001,"<"&EDATE($V3,1),Orders!$E$2:$E$2001,AA$1) -> 57914.81 | AB3: =SUMIFS(Orders!$I$2:$I$2001,Orders!$B$2:$B$2001,">="&$V3,Orders!$B$2:$B$2001,"<"&EDATE($V3,1),Orders!$E$2:$E$2001,AB$1) -> 34581.99 | AC3: =SUMIFS(Orders!$I$2:$I$2001,Orders!$B$2:$B$2001,">="&$V3,Orders!$B$2:$B$2001,"<"&EDATE($V3,1),Orders!$E$2:$E$2001,AC$1) -> 130276.04 | AD3: =SUMIFS(Orders!$I$2:$I$2001,Orders!$B$2:$B$2001,">="&$V3,Orders!$B$2:$B$2001,"<"&EDATE($V3,1),Orders!$E$2:$E$2001,AD$1) -> 23463.3 | ... AZ3: =SUMIFS(Orders!$I$2:$I$2001,Orders!$B$2:$B$2001,">="&$V3,Orders!$B$2:$B$2001,"<"&EDATE($V3,1),Orders!$E$2:$E$2001,AZ$1) -> 17274.29
A4: =Orders!A4 -> ORD-00003 | B4: =PROPER(TRIM(Orders!K4)) -> Delhi | C4: =IFERROR(VLOOKUP(Orders!D4,Products!$A$2:$F$61,3,FALSE()),"Not Found") -> Sports | D4: =IFERROR(VLOOKUP(Orders!C4,Customers!$A$2:$F$301,5,FALSE()),"Not Found") -> Retail | E4: =IFERROR(VLOOKUP(Orders!C4,Customers!$A$2:$F$301,3,FALSE()),"Not Found") -> 52 | F4: =IFERROR(VLOOKUP(Orders!E4,Sales_Reps!$A$2:$E$31,3,FALSE()),"Not Found") -> South | G4: =IFERROR(VLOOKUP(Orders!D4,Products!$A$2:$F$61,4,FALSE()),"") -> 302 | H4: =IF(G4="","",(Orders!G4-G4)/Orders!G4) -> 0.35744681 | J4: =Sales_Reps!A4 -> R003 | K4: =Sales_Reps!B4 -> Amit Singh | L4: =SUMIFS(Orders!$I$2:$I$2001,Orders!$E$2:$E$2001,J4) -> 986692.91 | M4: =RANK(L4,$L$2:$L$31,0) -> 7 | O4: 3 | P4: =INDEX($K$2:$K$31,MATCH(LARGE($L$2:$L$31,O4),$L$2:$L$31,0)) -> Deepak Shah | R4: =Products!A4 -> PROD-003 | S4: =Products!B4 -> Smart Watch | T4: =SUMIFS(Orders!$I$2:$I$2001,Orders!$D$2:$D$2001,R4,$F$2:$F$2001,"West") -> 248025.75 | V4: =EDATE(V3,1) -> 45352 | W4: =SUMIFS(Orders!$I$2:$I$2001,Orders!$B$2:$B$2001,">="&$V4,Orders!$B$2:$B$2001,"<"&EDATE($V4,1),Orders!$E$2:$E$2001,W$1) -> 58208.49 | X4: =SUMIFS(Orders!$I$2:$I$2001,Orders!$B$2:$B$2001,">="&$V4,Orders!$B$2:$B$2001,"<"&EDATE($V4,1),Orders!$E$2:$E$2001,X$1) -> 53533 | Y4: =SUMIFS(Orders!$I$2:$I$2001,Orders!$B$2:$B$2001,">="&$V4,Orders!$B$2:$B$2001,"<"&EDATE($V4,1),Orders!$E$2:$E$2001,Y$1) -> 107489.23 | Z4: =SUMIFS(Orders!$I$2:$I$2001,Orders!$B$2:$B$2001,">="&$V4,Orders!$B$2:$B$2001,"<"&EDATE($V4,1),Orders!$E$2:$E$2001,Z$1) -> 14394.38 | AA4: =SUMIFS(Orders!$I$2:$I$2001,Orders!$B$2:$B$2001,">="&$V4,Orders!$B$2:$B$2001,"<"&EDATE($V4,1),Orders!$E$2:$E$2001,AA$1) -> 85853.43 | AB4: =SUMIFS(Orders!$I$2:$I$2001,Orders!$B$2:$B$2001,">="&$V4,Orders!$B$2:$B$2001,"<"&EDATE($V4,1),Orders!$E$2:$E$2001,AB$1) -> 145435.13 | AC4: =SUMIFS(Orders!$I$2:$I$2001,Orders!$B$2:$B$2001,">="&$V4,Orders!$B$2:$B$2001,"<"&EDATE($V4,1),Orders!$E$2:$E$2001,AC$1) -> 105489.83 | AD4: =SUMIFS(Orders!$I$2:$I$2001,Orders!$B$2:$B$2001,">="&$V4,Orders!$B$2:$B$2001,"<"&EDATE($V4,1),Orders!$E$2:$E$2001,AD$1) -> 164615.05 | ... AZ4: =SUMIFS(Orders!$I$2:$I$2001,Orders!$B$2:$B$2001,">="&$V4,Orders!$B$2:$B$2001,"<"&EDATE($V4,1),Orders!$E$2:$E$2001,AZ$1) -> 122041.06
A5: =Orders!A5 -> ORD-00004 | B5: =PROPER(TRIM(Orders!K5)) -> Delhi | C5: =IFERROR(VLOOKUP(Orders!D5,Products!$A$2:$F$61,3,FALSE()),"Not Found") -> Grocery | D5: =IFERROR(VLOOKUP(Orders!C5,Customers!$A$2:$F$301,5,FALSE()),"Not Found") -> Corporate | E5: =IFERROR(VLOOKUP(Orders!C5,Customers!$A$2:$F$301,3,FALSE()),"Not Found") -> 46 | F5: =IFERROR(VLOOKUP(Orders!E5,Sales_Reps!$A$2:$E$31,3,FALSE()),"Not Found") -> North | G5: =IFERROR(VLOOKUP(Orders!D5,Products!$A$2:$F$61,4,FALSE()),"") -> 2214 | H5: =IF(G5="","",(Orders!G5-G5)/Orders!G5) -> 0.39508197 | J5: =Sales_Reps!A5 -> R004 | K5: =Sales_Reps!B5 -> Priya Singh | L5: =SUMIFS(Orders!$I$2:$I$2001,Orders!$E$2:$E$2001,J5) -> 589026.29 | M5: =RANK(L5,$L$2:$L$31,0) -> 29 | O5: 4 | P5: =INDEX($K$2:$K$31,MATCH(LARGE($L$2:$L$31,O5),$L$2:$L$31,0)) -> Nisha Menon | R5: =Products!A5 -> PROD-004 | S5: =Products!B5 -> Laptop Bag | T5: =SUMIFS(Orders!$I$2:$I$2001,Orders!$D$2:$D$2001,R5,$F$2:$F$2001,"West") -> 198124.65 | V5: =EDATE(V4,1) -> 45383 | W5: =SUMIFS(Orders!$I$2:$I$2001,Orders!$B$2:$B$2001,">="&$V5,Orders!$B$2:$B$2001,"<"&EDATE($V5,1),Orders!$E$2:$E$2001,W$1) -> 33643.48 | X5: =SUMIFS(Orders!$I$2:$I$2001,Orders!$B$2:$B$2001,">="&$V5,Orders!$B$2:$B$2001,"<"&EDATE($V5,1),Orders!$E$2:$E$2001,X$1) -> 46286.92 | Y5: =SUMIFS(Orders!$I$2:$I$2001,Orders!$B$2:$B$2001,">="&$V5,Orders!$B$2:$B$2001,"<"&EDATE($V5,1),Orders!$E$2:$E$2001,Y$1) -> 96349.86 | Z5: =SUMIFS(Orders!$I$2:$I$2001,Orders!$B$2:$B$2001,">="&$V5,Orders!$B$2:$B$2001,"<"&EDATE($V5,1),Orders!$E$2:$E$2001,Z$1) -> 23036.54 | AA5: =SUMIFS(Orders!$I$2:$I$2001,Orders!$B$2:$B$2001,">="&$V5,Orders!$B$2:$B$2001,"<"&EDATE($V5,1),Orders!$E$2:$E$2001,AA$1) -> 46025.56 | AB5: =SUMIFS(Orders!$I$2:$I$2001,Orders!$B$2:$B$2001,">="&$V5,Orders!$B$2:$B$2001,"<"&EDATE($V5,1),Orders!$E$2:$E$2001,AB$1) -> 170939.91 | AC5: =SUMIFS(Orders!$I$2:$I$2001,Orders!$B$2:$B$2001,">="&$V5,Orders!$B$2:$B$2001,"<"&EDATE($V5,1),Orders!$E$2:$E$2001,AC$1) -> 48536.18 | AD5: =SUMIFS(Orders!$I$2:$I$2001,Orders!$B$2:$B$2001,">="&$V5,Orders!$B$2:$B$2001,"<"&EDATE($V5,1),Orders!$E$2:$E$2001,AD$1) -> 12044.56 | ... AZ5: =SUMIFS(Orders!$I$2:$I$2001,Orders!$B$2:$B$2001,">="&$V5,Orders!$B$2:$B$2001,"<"&EDATE($V5,1),Orders!$E$2:$E$2001,AZ$1) -> 36350.86
A6: =Orders!A6 -> ORD-00005 | B6: =PROPER(TRIM(Orders!K6)) -> Chennai | C6: =IFERROR(VLOOKUP(Orders!D6,Products!$A$2:$F$61,3,FALSE()),"Not Found") -> Apparel | D6: =IFERROR(VLOOKUP(Orders!C6,Customers!$A$2:$F$301,5,FALSE()),"Not Found") -> Retail | E6: =IFERROR(VLOOKUP(Orders!C6,Customers!$A$2:$F$301,3,FALSE()),"Not Found") -> 36 | F6: =IFERROR(VLOOKUP(Orders!E6,Sales_Reps!$A$2:$E$31,3,FALSE()),"Not Found") -> North | G6: =IFERROR(VLOOKUP(Orders!D6,Products!$A$2:$F$61,4,FALSE()),"") -> 1886 | H6: =IF(G6="","",(Orders!G6-G6)/Orders!G6) -> 0.40316456 | J6: =Sales_Reps!A6 -> R005 | K6: =Sales_Reps!B6 -> Vikram Patel | L6: =SUMIFS(Orders!$I$2:$I$2001,Orders!$E$2:$E$2001,J6) -> 782445.33 | M6: =RANK(L6,$L$2:$L$31,0) -> 24 | O6: 5 | P6: =INDEX($K$2:$K$31,MATCH(LARGE($L$2:$L$31,O6),$L$2:$L$31,0)) -> Arun Iyer | R6: =Products!A6 -> PROD-005 | S6: =Products!B6 -> Power Bank | T6: =SUMIFS(Orders!$I$2:$I$2001,Orders!$D$2:$D$2001,R6,$F$2:$F$2001,"West") -> 7449.9 | V6: =EDATE(V5,1) -> 45413 | W6: =SUMIFS(Orders!$I$2:$I$2001,Orders!$B$2:$B$2001,">="&$V6,Orders!$B$2:$B$2001,"<"&EDATE($V6,1),Orders!$E$2:$E$2001,W$1) -> 44809.66 | X6: =SUMIFS(Orders!$I$2:$I$2001,Orders!$B$2:$B$2001,">="&$V6,Orders!$B$2:$B$2001,"<"&EDATE($V6,1),Orders!$E$2:$E$2001,X$1) -> 89794.86 | Y6: =SUMIFS(Orders!$I$2:$I$2001,Orders!$B$2:$B$2001,">="&$V6,Orders!$B$2:$B$2001,"<"&EDATE($V6,1),Orders!$E$2:$E$2001,Y$1) -> 139257.72 | Z6: =SUMIFS(Orders!$I$2:$I$2001,Orders!$B$2:$B$2001,">="&$V6,Orders!$B$2:$B$2001,"<"&EDATE($V6,1),Orders!$E$2:$E$2001,Z$1) -> 140739.8 | AA6: =SUMIFS(Orders!$I$2:$I$2001,Orders!$B$2:$B$2001,">="&$V6,Orders!$B$2:$B$2001,"<"&EDATE($V6,1),Orders!$E$2:$E$2001,AA$1) -> 67702.82 | AB6: =SUMIFS(Orders!$I$2:$I$2001,Orders!$B$2:$B$2001,">="&$V6,Orders!$B$2:$B$2001,"<"&EDATE($V6,1),Orders!$E$2:$E$2001,AB$1) -> 78322.48 | AC6: =SUMIFS(Orders!$I$2:$I$2001,Orders!$B$2:$B$2001,">="&$V6,Orders!$B$2:$B$2001,"<"&EDATE($V6,1),Orders!$E$2:$E$2001,AC$1) -> 41157.84 | AD6: =SUMIFS(Orders!$I$2:$I$2001,Orders!$B$2:$B$2001,">="&$V6,Orders!$B$2:$B$2001,"<"&EDATE($V6,1),Orders!$E$2:$E$2001,AD$1) -> 67200.57 | ... AZ6: =SUMIFS(Orders!$I$2:$I$2001,Orders!$B$2:$B$2001,">="&$V6,Orders!$B$2:$B$2001,"<"&EDATE($V6,1),Orders!$E$2:$E$2001,AZ$1) -> 47579.17
A7: =Orders!A7 -> ORD-00006 | B7: =PROPER(TRIM(Orders!K7)) -> Mumbai | C7: =IFERROR(VLOOKUP(Orders!D7,Products!$A$2:$F$61,3,FALSE()),"Not Found") -> Home | D7: =IFERROR(VLOOKUP(Orders!C7,Customers!$A$2:$F$301,5,FALSE()),"Not Found") -> Retail | E7: =IFERROR(VLOOKUP(Orders!C7,Customers!$A$2:$F$301,3,FALSE()),"Not Found") -> 36 | F7: =IFERROR(VLOOKUP(Orders!E7,Sales_Reps!$A$2:$E$31,3,FALSE()),"Not Found") -> West | G7: =IFERROR(VLOOKUP(Orders!D7,Products!$A$2:$F$61,4,FALSE()),"") -> 288 | H7: =IF(G7="","",(Orders!G7-G7)/Orders!G7) -> 0.22162162 | J7: =Sales_Reps!A7 -> R006 | K7: =Sales_Reps!B7 -> Neha Desai | L7: =SUMIFS(Orders!$I$2:$I$2001,Orders!$E$2:$E$2001,J7) -> 1138648.7 | M7: =RANK(L7,$L$2:$L$31,0) -> 1 | R7: =Products!A7 -> PROD-006 | S7: =Products!B7 -> Bluetooth Speaker | T7: =SUMIFS(Orders!$I$2:$I$2001,Orders!$D$2:$D$2001,R7,$F$2:$F$2001,"West") -> 100869.76 | V7: =EDATE(V6,1) -> 45444 | W7: =SUMIFS(Orders!$I$2:$I$2001,Orders!$B$2:$B$2001,">="&$V7,Orders!$B$2:$B$2001,"<"&EDATE($V7,1),Orders!$E$2:$E$2001,W$1) -> 82789.95 | X7: =SUMIFS(Orders!$I$2:$I$2001,Orders!$B$2:$B$2001,">="&$V7,Orders!$B$2:$B$2001,"<"&EDATE($V7,1),Orders!$E$2:$E$2001,X$1) -> 82753.37 | Y7: =SUMIFS(Orders!$I$2:$I$2001,Orders!$B$2:$B$2001,">="&$V7,Orders!$B$2:$B$2001,"<"&EDATE($V7,1),Orders!$E$2:$E$2001,Y$1) -> 37966.09 | Z7: =SUMIFS(Orders!$I$2:$I$2001,Orders!$B$2:$B$2001,">="&$V7,Orders!$B$2:$B$2001,"<"&EDATE($V7,1),Orders!$E$2:$E$2001,Z$1) -> 42388.12 | AA7: =SUMIFS(Orders!$I$2:$I$2001,Orders!$B$2:$B$2001,">="&$V7,Orders!$B$2:$B$2001,"<"&EDATE($V7,1),Orders!$E$2:$E$2001,AA$1) -> 113205.32 | AB7: =SUMIFS(Orders!$I$2:$I$2001,Orders!$B$2:$B$2001,">="&$V7,Orders!$B$2:$B$2001,"<"&EDATE($V7,1),Orders!$E$2:$E$2001,AB$1) -> 191251.6 | AC7: =SUMIFS(Orders!$I$2:$I$2001,Orders!$B$2:$B$2001,">="&$V7,Orders!$B$2:$B$2001,"<"&EDATE($V7,1),Orders!$E$2:$E$2001,AC$1) -> 58895.11 | AD7: =SUMIFS(Orders!$I$2:$I$2001,Orders!$B$2:$B$2001,">="&$V7,Orders!$B$2:$B$2001,"<"&EDATE($V7,1),Orders!$E$2:$E$2001,AD$1) -> 82481.44 | ... AZ7: =SUMIFS(Orders!$I$2:$I$2001,Orders!$B$2:$B$2001,">="&$V7,Orders!$B$2:$B$2001,"<"&EDATE($V7,1),Orders!$E$2:$E$2001,AZ$1) -> 67486.9
A8: =Orders!A8 -> ORD-00007 | B8: =PROPER(TRIM(Orders!K8)) -> Bengaluru | C8: =IFERROR(VLOOKUP(Orders!D8,Products!$A$2:$F$61,3,FALSE()),"Not Found") -> Sports | D8: =IFERROR(VLOOKUP(Orders!C8,Customers!$A$2:$F$301,5,FALSE()),"Not Found") -> Retail | E8: =IFERROR(VLOOKUP(Orders!C8,Customers!$A$2:$F$301,3,FALSE()),"Not Found") -> 27 | F8: =IFERROR(VLOOKUP(Orders!E8,Sales_Reps!$A$2:$E$31,3,FALSE()),"Not Found") -> West | G8: =IFERROR(VLOOKUP(Orders!D8,Products!$A$2:$F$61,4,FALSE()),"") -> 705 | H8: =IF(G8="","",(Orders!G8-G8)/Orders!G8) -> 0.265625 | J8: =Sales_Reps!A8 -> R007 | K8: =Sales_Reps!B8 -> Suresh Menon | L8: =SUMIFS(Orders!$I$2:$I$2001,Orders!$E$2:$E$2001,J8) -> 855749.68 | M8: =RANK(L8,$L$2:$L$31,0) -> 19 | R8: =Products!A8 -> PROD-007 | S8: =Products!B8 -> USB-C Cable | T8: =SUMIFS(Orders!$I$2:$I$2001,Orders!$D$2:$D$2001,R8,$F$2:$F$2001,"West") -> 38531.35 | V8: =EDATE(V7,1) -> 45474 | W8: =SUMIFS(Orders!$I$2:$I$2001,Orders!$B$2:$B$2001,">="&$V8,Orders!$B$2:$B$2001,"<"&EDATE($V8,1),Orders!$E$2:$E$2001,W$1) -> 28761.2 | X8: =SUMIFS(Orders!$I$2:$I$2001,Orders!$B$2:$B$2001,">="&$V8,Orders!$B$2:$B$2001,"<"&EDATE($V8,1),Orders!$E$2:$E$2001,X$1) -> 62949.74 | Y8: =SUMIFS(Orders!$I$2:$I$2001,Orders!$B$2:$B$2001,">="&$V8,Orders!$B$2:$B$2001,"<"&EDATE($V8,1),Orders!$E$2:$E$2001,Y$1) -> 185921.75 | Z8: =SUMIFS(Orders!$I$2:$I$2001,Orders!$B$2:$B$2001,">="&$V8,Orders!$B$2:$B$2001,"<"&EDATE($V8,1),Orders!$E$2:$E$2001,Z$1) -> 7823.48 | AA8: =SUMIFS(Orders!$I$2:$I$2001,Orders!$B$2:$B$2001,">="&$V8,Orders!$B$2:$B$2001,"<"&EDATE($V8,1),Orders!$E$2:$E$2001,AA$1) -> 20649.35 | AB8: =SUMIFS(Orders!$I$2:$I$2001,Orders!$B$2:$B$2001,">="&$V8,Orders!$B$2:$B$2001,"<"&EDATE($V8,1),Orders!$E$2:$E$2001,AB$1) -> 38479.32 | AC8: =SUMIFS(Orders!$I$2:$I$2001,Orders!$B$2:$B$2001,">="&$V8,Orders!$B$2:$B$2001,"<"&EDATE($V8,1),Orders!$E$2:$E$2001,AC$1) -> 11528.24 | AD8: =SUMIFS(Orders!$I$2:$I$2001,Orders!$B$2:$B$2001,">="&$V8,Orders!$B$2:$B$2001,"<"&EDATE($V8,1),Orders!$E$2:$E$2001,AD$1) -> 75853.47 | ... AZ8: =SUMIFS(Orders!$I$2:$I$2001,Orders!$B$2:$B$2001,">="&$V8,Orders!$B$2:$B$2001,"<"&EDATE($V8,1),Orders!$E$2:$E$2001,AZ$1) -> 89271.18
A9: =Orders!A9 -> ORD-00008 | B9: =PROPER(TRIM(Orders!K9)) -> Bengaluru | C9: =IFERROR(VLOOKUP(Orders!D9,Products!$A$2:$F$61,3,FALSE()),"Not Found") -> Electronics | D9: =IFERROR(VLOOKUP(Orders!C9,Customers!$A$2:$F$301,5,FALSE()),"Not Found") -> Corporate | E9: =IFERROR(VLOOKUP(Orders!C9,Customers!$A$2:$F$301,3,FALSE()),"Not Found") -> 57 | F9: =IFERROR(VLOOKUP(Orders!E9,Sales_Reps!$A$2:$E$31,3,FALSE()),"Not Found") -> East | G9: =IFERROR(VLOOKUP(Orders!D9,Products!$A$2:$F$61,4,FALSE()),"") -> 861 | H9: =IF(G9="","",(Orders!G9-G9)/Orders!G9) -> 0.3979021 | J9: =Sales_Reps!A9 -> R008 | K9: =Sales_Reps!B9 -> Kavita Patel | L9: =SUMIFS(Orders!$I$2:$I$2001,Orders!$E$2:$E$2001,J9) -> 861553.33 | M9: =RANK(L9,$L$2:$L$31,0) -> 18 | R9: =Products!A9 -> PROD-008 | S9: =Products!B9 -> Wireless Mouse | T9: =SUMIFS(Orders!$I$2:$I$2001,Orders!$D$2:$D$2001,R9,$F$2:$F$2001,"West") -> 7807.1 | V9: =EDATE(V8,1) -> 45505 | W9: =SUMIFS(Orders!$I$2:$I$2001,Orders!$B$2:$B$2001,">="&$V9,Orders!$B$2:$B$2001,"<"&EDATE($V9,1),Orders!$E$2:$E$2001,W$1) -> 92676.92 | X9: =SUMIFS(Orders!$I$2:$I$2001,Orders!$B$2:$B$2001,">="&$V9,Orders!$B$2:$B$2001,"<"&EDATE($V9,1),Orders!$E$2:$E$2001,X$1) -> 134500.5 | Y9: =SUMIFS(Orders!$I$2:$I$2001,Orders!$B$2:$B$2001,">="&$V9,Orders!$B$2:$B$2001,"<"&EDATE($V9,1),Orders!$E$2:$E$2001,Y$1) -> 114656.27 | Z9: =SUMIFS(Orders!$I$2:$I$2001,Orders!$B$2:$B$2001,">="&$V9,Orders!$B$2:$B$2001,"<"&EDATE($V9,1),Orders!$E$2:$E$2001,Z$1) -> 55975.34 | AA9: =SUMIFS(Orders!$I$2:$I$2001,Orders!$B$2:$B$2001,">="&$V9,Orders!$B$2:$B$2001,"<"&EDATE($V9,1),Orders!$E$2:$E$2001,AA$1) -> 15060.28 | AB9: =SUMIFS(Orders!$I$2:$I$2001,Orders!$B$2:$B$2001,">="&$V9,Orders!$B$2:$B$2001,"<"&EDATE($V9,1),Orders!$E$2:$E$2001,AB$1) -> 61857.9 | AC9: =SUMIFS(Orders!$I$2:$I$2001,Orders!$B$2:$B$2001,">="&$V9,Orders!$B$2:$B$2001,"<"&EDATE($V9,1),Orders!$E$2:$E$2001,AC$1) -> 70196.8 | AD9: =SUMIFS(Orders!$I$2:$I$2001,Orders!$B$2:$B$2001,">="&$V9,Orders!$B$2:$B$2001,"<"&EDATE($V9,1),Orders!$E$2:$E$2001,AD$1) -> 61043.44 | ... AZ9: =SUMIFS(Orders!$I$2:$I$2001,Orders!$B$2:$B$2001,">="&$V9,Orders!$B$2:$B$2001,"<"&EDATE($V9,1),Orders!$E$2:$E$2001,AZ$1) -> 74000.9
A10: =Orders!A10 -> ORD-00009 | B10: =PROPER(TRIM(Orders!K10)) -> Bengaluru | C10: =IFERROR(VLOOKUP(Orders!D10,Products!$A$2:$F$61,3,FALSE()),"Not Found") -> Home | D10: =IFERROR(VLOOKUP(Orders!C10,Customers!$A$2:$F$301,5,FALSE()),"Not Found") -> Retail | E10: =IFERROR(VLOOKUP(Orders!C10,Customers!$A$2:$F$301,3,FALSE()),"Not Found") -> 42 | F10: =IFERROR(VLOOKUP(Orders!E10,Sales_Reps!$A$2:$E$31,3,FALSE()),"Not Found") -> North | G10: =IFERROR(VLOOKUP(Orders!D10,Products!$A$2:$F$61,4,FALSE()),"") -> 2549 | H10: =IF(G10="","",(Orders!G10-G10)/Orders!G10) -> 0.53570128 | J10: =Sales_Reps!A10 -> R009 | K10: =Sales_Reps!B10 -> Manoj Patel | L10: =SUMIFS(Orders!$I$2:$I$2001,Orders!$E$2:$E$2001,J10) -> 914554.72 | M10: =RANK(L10,$L$2:$L$31,0) -> 12 | R10: =Products!A10 -> PROD-009 | S10: =Products!B10 -> Mechanical Keyboard | T10: =SUMIFS(Orders!$I$2:$I$2001,Orders!$D$2:$D$2001,R10,$F$2:$F$2001,"West") -> 64207.38 | V10: =EDATE(V9,1) -> 45536 | W10: =SUMIFS(Orders!$I$2:$I$2001,Orders!$B$2:$B$2001,">="&$V10,Orders!$B$2:$B$2001,"<"&EDATE($V10,1),Orders!$E$2:$E$2001,W$1) -> 88884.34 | X10: =SUMIFS(Orders!$I$2:$I$2001,Orders!$B$2:$B$2001,">="&$V10,Orders!$B$2:$B$2001,"<"&EDATE($V10,1),Orders!$E$2:$E$2001,X$1) -> 91647.29 | Y10: =SUMIFS(Orders!$I$2:$I$2001,Orders!$B$2:$B$2001,">="&$V10,Orders!$B$2:$B$2001,"<"&EDATE($V10,1),Orders!$E$2:$E$2001,Y$1) -> 69896.72 | Z10: =SUMIFS(Orders!$I$2:$I$2001,Orders!$B$2:$B$2001,">="&$V10,Orders!$B$2:$B$2001,"<"&EDATE($V10,1),Orders!$E$2:$E$2001,Z$1) -> 46944.28 | AA10: =SUMIFS(Orders!$I$2:$I$2001,Orders!$B$2:$B$2001,">="&$V10,Orders!$B$2:$B$2001,"<"&EDATE($V10,1),Orders!$E$2:$E$2001,AA$1) -> 81963.69 | AB10: =SUMIFS(Orders!$I$2:$I$2001,Orders!$B$2:$B$2001,">="&$V10,Orders!$B$2:$B$2001,"<"&EDATE($V10,1),Orders!$E$2:$E$2001,AB$1) -> 76627.83 | AC10: =SUMIFS(Orders!$I$2:$I$2001,Orders!$B$2:$B$2001,">="&$V10,Orders!$B$2:$B$2001,"<"&EDATE($V10,1),Orders!$E$2:$E$2001,AC$1) -> 52194.15 | AD10: =SUMIFS(Orders!$I$2:$I$2001,Orders!$B$2:$B$2001,">="&$V10,Orders!$B$2:$B$2001,"<"&EDATE($V10,1),Orders!$E$2:$E$2001,AD$1) -> 49404.64 | ... AZ10: =SUMIFS(Orders!$I$2:$I$2001,Orders!$B$2:$B$2001,">="&$V10,Orders!$B$2:$B$2001,"<"&EDATE($V10,1),Orders!$E$2:$E$2001,AZ$1) -> 26448.21
A11: =Orders!A11 -> ORD-00010 | B11: =PROPER(TRIM(Orders!K11)) -> Pune | C11: =IFERROR(VLOOKUP(Orders!D11,Products!$A$2:$F$61,3,FALSE()),"Not Found") -> Grocery | D11: =IFERROR(VLOOKUP(Orders!C11,Customers!$A$2:$F$301,5,FALSE()),"Not Found") -> Retail | E11: =IFERROR(VLOOKUP(Orders!C11,Customers!$A$2:$F$301,3,FALSE()),"Not Found") -> 56 | F11: =IFERROR(VLOOKUP(Orders!E11,Sales_Reps!$A$2:$E$31,3,FALSE()),"Not Found") -> West | G11: =IFERROR(VLOOKUP(Orders!D11,Products!$A$2:$F$61,4,FALSE()),"") -> 434 | H11: =IF(G11="","",(Orders!G11-G11)/Orders!G11) -> 0.55257732 | J11: =Sales_Reps!A11 -> R010 | K11: =Sales_Reps!B11 -> Divya Rao | L11: =SUMIFS(Orders!$I$2:$I$2001,Orders!$E$2:$E$2001,J11) -> 880345.2 | M11: =RANK(L11,$L$2:$L$31,0) -> 17 | R11: =Products!A11 -> PROD-010 | S11: =Products!B11 -> Tablet Stand | T11: =SUMIFS(Orders!$I$2:$I$2001,Orders!$D$2:$D$2001,R11,$F$2:$F$2001,"West") -> 67393.92 | V11: =EDATE(V10,1) -> 45566 | W11: =SUMIFS(Orders!$I$2:$I$2001,Orders!$B$2:$B$2001,">="&$V11,Orders!$B$2:$B$2001,"<"&EDATE($V11,1),Orders!$E$2:$E$2001,W$1) -> 37753.9 | X11: =SUMIFS(Orders!$I$2:$I$2001,Orders!$B$2:$B$2001,">="&$V11,Orders!$B$2:$B$2001,"<"&EDATE($V11,1),Orders!$E$2:$E$2001,X$1) -> 35751.81 | Y11: =SUMIFS(Orders!$I$2:$I$2001,Orders!$B$2:$B$2001,">="&$V11,Orders!$B$2:$B$2001,"<"&EDATE($V11,1),Orders!$E$2:$E$2001,Y$1) -> 29309.98 | Z11: =SUMIFS(Orders!$I$2:$I$2001,Orders!$B$2:$B$2001,">="&$V11,Orders!$B$2:$B$2001,"<"&EDATE($V11,1),Orders!$E$2:$E$2001,Z$1) -> 43456.18 | AA11: =SUMIFS(Orders!$I$2:$I$2001,Orders!$B$2:$B$2001,">="&$V11,Orders!$B$2:$B$2001,"<"&EDATE($V11,1),Orders!$E$2:$E$2001,AA$1) -> 99252.77 | AB11: =SUMIFS(Orders!$I$2:$I$2001,Orders!$B$2:$B$2001,">="&$V11,Orders!$B$2:$B$2001,"<"&EDATE($V11,1),Orders!$E$2:$E$2001,AB$1) -> 52942.27 | AC11: =SUMIFS(Orders!$I$2:$I$2001,Orders!$B$2:$B$2001,">="&$V11,Orders!$B$2:$B$2001,"<"&EDATE($V11,1),Orders!$E$2:$E$2001,AC$1) -> 57313.75 | AD11: =SUMIFS(Orders!$I$2:$I$2001,Orders!$B$2:$B$2001,">="&$V11,Orders!$B$2:$B$2001,"<"&EDATE($V11,1),Orders!$E$2:$E$2001,AD$1) -> 26620.46 | ... AZ11: =SUMIFS(Orders!$I$2:$I$2001,Orders!$B$2:$B$2001,">="&$V11,Orders!$B$2:$B$2001,"<"&EDATE($V11,1),Orders!$E$2:$E$2001,AZ$1) -> 40669.76
A12: =Orders!A12 -> ORD-00011 | B12: =PROPER(TRIM(Orders!K12)) -> Hyderabad | C12: =IFERROR(VLOOKUP(Orders!D12,Products!$A$2:$F$61,3,FALSE()),"Not Found") -> Grocery | D12: =IFERROR(VLOOKUP(Orders!C12,Customers!$A$2:$F$301,5,FALSE()),"Not Found") -> Retail | E12: =IFERROR(VLOOKUP(Orders!C12,Customers!$A$2:$F$301,3,FALSE()),"Not Found") -> 60 | F12: =IFERROR(VLOOKUP(Orders!E12,Sales_Reps!$A$2:$E$31,3,FALSE()),"Not Found") -> South | G12: =IFERROR(VLOOKUP(Orders!D12,Products!$A$2:$F$61,4,FALSE()),"") -> 1203 | H12: =IF(G12="","",(Orders!G12-G12)/Orders!G12) -> 0.47004405 | J12: =Sales_Reps!A12 -> R011 | K12: =Sales_Reps!B12 -> Anil Verma | L12: =SUMIFS(Orders!$I$2:$I$2001,Orders!$E$2:$E$2001,J12) -> 735207.76 | M12: =RANK(L12,$L$2:$L$31,0) -> 28 | R12: =Products!A12 -> PROD-011 | S12: =Products!B12 -> Cotton T-Shirt | T12: =SUMIFS(Orders!$I$2:$I$2001,Orders!$D$2:$D$2001,R12,$F$2:$F$2001,"West") -> 145224.3 | V12: =EDATE(V11,1) -> 45597 | W12: =SUMIFS(Orders!$I$2:$I$2001,Orders!$B$2:$B$2001,">="&$V12,Orders!$B$2:$B$2001,"<"&EDATE($V12,1),Orders!$E$2:$E$2001,W$1) -> 72215.41 | X12: =SUMIFS(Orders!$I$2:$I$2001,Orders!$B$2:$B$2001,">="&$V12,Orders!$B$2:$B$2001,"<"&EDATE($V12,1),Orders!$E$2:$E$2001,X$1) -> 158277.82 | Y12: =SUMIFS(Orders!$I$2:$I$2001,Orders!$B$2:$B$2001,">="&$V12,Orders!$B$2:$B$2001,"<"&EDATE($V12,1),Orders!$E$2:$E$2001,Y$1) -> 106760.75 | Z12: =SUMIFS(Orders!$I$2:$I$2001,Orders!$B$2:$B$2001,">="&$V12,Orders!$B$2:$B$2001,"<"&EDATE($V12,1),Orders!$E$2:$E$2001,Z$1) -> 38491.18 | AA12: =SUMIFS(Orders!$I$2:$I$2001,Orders!$B$2:$B$2001,">="&$V12,Orders!$B$2:$B$2001,"<"&EDATE($V12,1),Orders!$E$2:$E$2001,AA$1) -> 55570.99 | AB12: =SUMIFS(Orders!$I$2:$I$2001,Orders!$B$2:$B$2001,">="&$V12,Orders!$B$2:$B$2001,"<"&EDATE($V12,1),Orders!$E$2:$E$2001,AB$1) -> 81500.24 | AC12: =SUMIFS(Orders!$I$2:$I$2001,Orders!$B$2:$B$2001,">="&$V12,Orders!$B$2:$B$2001,"<"&EDATE($V12,1),Orders!$E$2:$E$2001,AC$1) -> 130208.9 | AD12: =SUMIFS(Orders!$I$2:$I$2001,Orders!$B$2:$B$2001,">="&$V12,Orders!$B$2:$B$2001,"<"&EDATE($V12,1),Orders!$E$2:$E$2001,AD$1) -> 64537.26 | ... AZ12: =SUMIFS(Orders!$I$2:$I$2001,Orders!$B$2:$B$2001,">="&$V12,Orders!$B$2:$B$2001,"<"&EDATE($V12,1),Orders!$E$2:$E$2001,AZ$1) -> 119624.49
A13: =Orders!A13 -> ORD-00012 | B13: =PROPER(TRIM(Orders!K13)) -> Pune | C13: =IFERROR(VLOOKUP(Orders!D13,Products!$A$2:$F$61,3,FALSE()),"Not Found") -> Electronics | D13: =IFERROR(VLOOKUP(Orders!C13,Customers!$A$2:$F$301,5,FALSE()),"Not Found") -> Retail | E13: =IFERROR(VLOOKUP(Orders!C13,Customers!$A$2:$F$301,3,FALSE()),"Not Found") -> 56 | F13: =IFERROR(VLOOKUP(Orders!E13,Sales_Reps!$A$2:$E$31,3,FALSE()),"Not Found") -> West | G13: =IFERROR(VLOOKUP(Orders!D13,Products!$A$2:$F$61,4,FALSE()),"") -> 1149 | H13: =IF(G13="","",(Orders!G13-G13)/Orders!G13) -> 0.56477273 | J13: =Sales_Reps!A13 -> R012 | K13: =Sales_Reps!B13 -> Pooja Nair | L13: =SUMIFS(Orders!$I$2:$I$2001,Orders!$E$2:$E$2001,J13) -> 901394.32 | M13: =RANK(L13,$L$2:$L$31,0) -> 14 | R13: =Products!A13 -> PROD-012 | S13: =Products!B13 -> Denim Jeans | T13: =SUMIFS(Orders!$I$2:$I$2001,Orders!$D$2:$D$2001,R13,$F$2:$F$2001,"West") -> 121770.6 | V13: =EDATE(V12,1) -> 45627 | W13: =SUMIFS(Orders!$I$2:$I$2001,Orders!$B$2:$B$2001,">="&$V13,Orders!$B$2:$B$2001,"<"&EDATE($V13,1),Orders!$E$2:$E$2001,W$1) -> 79450.52 | X13: =SUMIFS(Orders!$I$2:$I$2001,Orders!$B$2:$B$2001,">="&$V13,Orders!$B$2:$B$2001,"<"&EDATE($V13,1),Orders!$E$2:$E$2001,X$1) -> 47673.25 | Y13: =SUMIFS(Orders!$I$2:$I$2001,Orders!$B$2:$B$2001,">="&$V13,Orders!$B$2:$B$2001,"<"&EDATE($V13,1),Orders!$E$2:$E$2001,Y$1) -> 12325.54 | Z13: =SUMIFS(Orders!$I$2:$I$2001,Orders!$B$2:$B$2001,">="&$V13,Orders!$B$2:$B$2001,"<"&EDATE($V13,1),Orders!$E$2:$E$2001,Z$1) -> 59066.32 | AA13: =SUMIFS(Orders!$I$2:$I$2001,Orders!$B$2:$B$2001,">="&$V13,Orders!$B$2:$B$2001,"<"&EDATE($V13,1),Orders!$E$2:$E$2001,AA$1) -> 68580.8 | AB13: =SUMIFS(Orders!$I$2:$I$2001,Orders!$B$2:$B$2001,">="&$V13,Orders!$B$2:$B$2001,"<"&EDATE($V13,1),Orders!$E$2:$E$2001,AB$1) -> 121741.5 | AC13: =SUMIFS(Orders!$I$2:$I$2001,Orders!$B$2:$B$2001,">="&$V13,Orders!$B$2:$B$2001,"<"&EDATE($V13,1),Orders!$E$2:$E$2001,AC$1) -> 57922.93 | AD13: =SUMIFS(Orders!$I$2:$I$2001,Orders!$B$2:$B$2001,">="&$V13,Orders!$B$2:$B$2001,"<"&EDATE($V13,1),Orders!$E$2:$E$2001,AD$1) -> 172732.12 | ... AZ13: =SUMIFS(Orders!$I$2:$I$2001,Orders!$B$2:$B$2001,">="&$V13,Orders!$B$2:$B$2001,"<"&EDATE($V13,1),Orders!$E$2:$E$2001,AZ$1) -> 47706.74
A14: =Orders!A14 -> ORD-00013 | B14: =PROPER(TRIM(Orders!K14)) -> Delhi | C14: =IFERROR(VLOOKUP(Orders!D14,Products!$A$2:$F$61,3,FALSE()),"Not Found") -> Electronics | D14: =IFERROR(VLOOKUP(Orders!C14,Customers!$A$2:$F$301,5,FALSE()),"Not Found") -> SMB | E14: =IFERROR(VLOOKUP(Orders!C14,Customers!$A$2:$F$301,3,FALSE()),"Not Found") -> 27 | F14: =IFERROR(VLOOKUP(Orders!E14,Sales_Reps!$A$2:$E$31,3,FALSE()),"Not Found") -> North | G14: =IFERROR(VLOOKUP(Orders!D14,Products!$A$2:$F$61,4,FALSE()),"") -> 1052 | H14: =IF(G14="","",(Orders!G14-G14)/Orders!G14) -> 0.59538462 | J14: =Sales_Reps!A14 -> R013 | K14: =Sales_Reps!B14 -> Sanjay Kapoor | L14: =SUMIFS(Orders!$I$2:$I$2001,Orders!$E$2:$E$2001,J14) -> 811524.38 | M14: =RANK(L14,$L$2:$L$31,0) -> 22 | R14: =Products!A14 -> PROD-013 | S14: =Products!B14 -> Formal Shirt | T14: =SUMIFS(Orders!$I$2:$I$2001,Orders!$D$2:$D$2001,R14,$F$2:$F$2001,"West") -> 85543.64
A15: =Orders!A15 -> ORD-00014 | B15: =PROPER(TRIM(Orders!K15)) -> Pune | C15: =IFERROR(VLOOKUP(Orders!D15,Products!$A$2:$F$61,3,FALSE()),"Not Found") -> Home | D15: =IFERROR(VLOOKUP(Orders!C15,Customers!$A$2:$F$301,5,FALSE()),"Not Found") -> SMB | E15: =IFERROR(VLOOKUP(Orders!C15,Customers!$A$2:$F$301,3,FALSE()),"Not Found") -> 39 | F15: =IFERROR(VLOOKUP(Orders!E15,Sales_Reps!$A$2:$E$31,3,FALSE()),"Not Found") -> West | G15: =IFERROR(VLOOKUP(Orders!D15,Products!$A$2:$F$61,4,FALSE()),"") -> 1556 | H15: =IF(G15="","",(Orders!G15-G15)/Orders!G15) -> 0.52123077 | J15: =Sales_Reps!A15 -> R014 | K15: =Sales_Reps!B15 -> Ritu Menon | L15: =SUMIFS(Orders!$I$2:$I$2001,Orders!$E$2:$E$2001,J15) -> 995713.54 | M15: =RANK(L15,$L$2:$L$31,0) -> 6 | R15: =Products!A15 -> PROD-014 | S15: =Products!B15 -> Winter Jacket | T15: =SUMIFS(Orders!$I$2:$I$2001,Orders!$D$2:$D$2001,R15,$F$2:$F$2001,"West") -> 95390.62
A16: =Orders!A16 -> ORD-00015 | B16: =PROPER(TRIM(Orders!K16)) -> Pune | C16: =IFERROR(VLOOKUP(Orders!D16,Products!$A$2:$F$61,3,FALSE()),"Not Found") -> Sports | D16: =IFERROR(VLOOKUP(Orders!C16,Customers!$A$2:$F$301,5,FALSE()),"Not Found") -> Retail | E16: =IFERROR(VLOOKUP(Orders!C16,Customers!$A$2:$F$301,3,FALSE()),"Not Found") -> 38 | F16: =IFERROR(VLOOKUP(Orders!E16,Sales_Reps!$A$2:$E$31,3,FALSE()),"Not Found") -> North | G16: =IFERROR(VLOOKUP(Orders!D16,Products!$A$2:$F$61,4,FALSE()),"") -> 147 | H16: =IF(G16="","",(Orders!G16-G16)/Orders!G16) -> 0.22631579 | J16: =Sales_Reps!A16 -> R015 | K16: =Sales_Reps!B16 -> Deepak Shah | L16: =SUMIFS(Orders!$I$2:$I$2001,Orders!$E$2:$E$2001,J16) -> 1091740.2 | M16: =RANK(L16,$L$2:$L$31,0) -> 3 | R16: =Products!A16 -> PROD-015 | S16: =Products!B16 -> Sports Shoes | T16: =SUMIFS(Orders!$I$2:$I$2001,Orders!$D$2:$D$2001,R16,$F$2:$F$2001,"West") -> 108190.72
A17: =Orders!A17 -> ORD-00016 | B17: =PROPER(TRIM(Orders!K17)) -> Pune | C17: =IFERROR(VLOOKUP(Orders!D17,Products!$A$2:$F$61,3,FALSE()),"Not Found") -> Sports | D17: =IFERROR(VLOOKUP(Orders!C17,Customers!$A$2:$F$301,5,FALSE()),"Not Found") -> Retail | E17: =IFERROR(VLOOKUP(Orders!C17,Customers!$A$2:$F$301,3,FALSE()),"Not Found") -> 63 | F17: =IFERROR(VLOOKUP(Orders!E17,Sales_Reps!$A$2:$E$31,3,FALSE()),"Not Found") -> South | G17: =IFERROR(VLOOKUP(Orders!D17,Products!$A$2:$F$61,4,FALSE()),"") -> 974 | H17: =IF(G17="","",(Orders!G17-G17)/Orders!G17) -> 0.59416667 | J17: =Sales_Reps!A17 -> R016 | K17: =Sales_Reps!B17 -> Anjali Chopra | L17: =SUMIFS(Orders!$I$2:$I$2001,Orders!$E$2:$E$2001,J17) -> 814563.71 | M17: =RANK(L17,$L$2:$L$31,0) -> 21 | R17: =Products!A17 -> PROD-016 | S17: =Products!B17 -> Casual Sneakers | T17: =SUMIFS(Orders!$I$2:$I$2001,Orders!$D$2:$D$2001,R17,$F$2:$F$2001,"West") -> 12964.82
A18: =Orders!A18 -> ORD-00017 | B18: =PROPER(TRIM(Orders!K18)) -> Bengaluru | C18: =IFERROR(VLOOKUP(Orders!D18,Products!$A$2:$F$61,3,FALSE()),"Not Found") -> Grocery | D18: =IFERROR(VLOOKUP(Orders!C18,Customers!$A$2:$F$301,5,FALSE()),"Not Found") -> SMB | E18: =IFERROR(VLOOKUP(Orders!C18,Customers!$A$2:$F$301,3,FALSE()),"Not Found") -> 46 | F18: =IFERROR(VLOOKUP(Orders!E18,Sales_Reps!$A$2:$E$31,3,FALSE()),"Not Found") -> East | G18: =IFERROR(VLOOKUP(Orders!D18,Products!$A$2:$F$61,4,FALSE()),"") -> 2214 | H18: =IF(G18="","",(Orders!G18-G18)/Orders!G18) -> 0.39508197 | J18: =Sales_Reps!A18 -> R017 | K18: =Sales_Reps!B18 -> Naveen Singh | L18: =SUMIFS(Orders!$I$2:$I$2001,Orders!$E$2:$E$2001,J18) -> 780384.41 | M18: =RANK(L18,$L$2:$L$31,0) -> 25 | R18: =Products!A18 -> PROD-017 | S18: =Products!B18 -> Silk Saree | T18: =SUMIFS(Orders!$I$2:$I$2001,Orders!$D$2:$D$2001,R18,$F$2:$F$2001,"West") -> 84699.95
A19: =Orders!A19 -> ORD-00018 | B19: =PROPER(TRIM(Orders!K19)) -> Hyderabad | C19: =IFERROR(VLOOKUP(Orders!D19,Products!$A$2:$F$61,3,FALSE()),"Not Found") -> Beauty | D19: =IFERROR(VLOOKUP(Orders!C19,Customers!$A$2:$F$301,5,FALSE()),"Not Found") -> Corporate | E19: =IFERROR(VLOOKUP(Orders!C19,Customers!$A$2:$F$301,3,FALSE()),"Not Found") -> 32 | F19: =IFERROR(VLOOKUP(Orders!E19,Sales_Reps!$A$2:$E$31,3,FALSE()),"Not Found") -> East | G19: =IFERROR(VLOOKUP(Orders!D19,Products!$A$2:$F$61,4,FALSE()),"") -> 2420 | H19: =IF(G19="","",(Orders!G19-G19)/Orders!G19) -> 0.29855072 | J19: =Sales_Reps!A19 -> R018 | K19: =Sales_Reps!B19 -> Shalini Patel | L19: =SUMIFS(Orders!$I$2:$I$2001,Orders!$E$2:$E$2001,J19) -> 1112289.6 | M19: =RANK(L19,$L$2:$L$31,0) -> 2 | R19: =Products!A19 -> PROD-018 | S19: =Products!B19 -> Kurta Set | T19: =SUMIFS(Orders!$I$2:$I$2001,Orders!$D$2:$D$2001,R19,$F$2:$F$2001,"West") -> 100288.76
